use failure::Error;

fn main() -> Result<(), Error> {
    git_together::run()
}
